Workbook

Sheet Лист38

Sheet  план 
B1: Бишкек | C1: филиал | D1: № группы | E1: Дата окончания обучения | F1: Количество обучающихся в группе | G1: Прогноз по переходу на стажировку | H1: Планируемое количество проектов
A2: июль | B2: PM | C2: Бишкекский | E2: 46241 | F2: 10 | G2: 4 | H2: 4
B4: UX/UI | C4: Бишкекский | D4: 60 | E4: 46231 | F4: 9 | G4: 4 | H4: 4
B5: UX/UI | C5: Внешние (Биш) | G5: 2
B6: UX/UI | C6: Ошский
B7: UX/UI | C7: Внешние (Ош)
B9: Backend | C9: Бишкекский | D9: 64-1,64-2 | E9: 46220 | F9: 23 | G9: 10 | H9: 4
B10: Backend | C10: Внешние (Биш) | G10: 2
B11: Backend | C11: Ошский
B12: Backend | C12: Внешние (Ош)
B14: Frontend | C14: Бишкекский | D14: 60-1,60-2 | E14: 46223 | F14: 12 | G14: 6 | H14: 4
B15: Frontend | C15: Внешние (Биш) | G15: 2
B16: Frontend | C16: Ошский | E16: 46209 | F16: 5 | G16: 4
B17: Frontend | C17: Внешние (Ош)
B19: Mobile | C19: Бишкекский | D19: Флаттер-03 | E19: 46200 | F19: 7 | G19: 3 | H19: 0-1
B20: Mobile | C20: Внешние (Биш) | G20: 1
B21: Mobile | C21: Ошский
B22: Mobile | C22: Внешние (Ош)
B24: Testing | C24: Бишкекский | D24: Т-32 | E24: 46223 | F24: 15 | G24: 6 | H24: 4
B25: Testing | C25: Внешние (Биш) | G25: 2
B26: Testing | C26: Ошский
B27: Testing | C27: Внешние (Ош)
A29: август | B29: PM | C29: Бишкекский
B31: UX/UI | C31: Бишкекский
B32: UX/UI | C32: Внешние (Биш)
B33: UX/UI | C33: Ошский | D33: 37-1 | E33: 46242
B34: UX/UI | C34: Внешние (Ош)
B36: Backend | C36: Бишкекский | L36: =56 -> 56 | M36: =77-56 -> 21 | N36: 11
B37: Backend | C37: Внешние (Биш)
B38: Backend | C38: Ошский | D38: 38-1 | E38: 46255
B39: Backend | C39: Внешние (Ош)
B41: Frontend | C41: Бишкекский
B42: Frontend | C42: Внешние (Биш)
B43: Frontend | C43: Ошский
B44: Frontend | C44: Внешние (Ош)
B46: Mobile | C46: Бишкекский
B47: Mobile | C47: Внешние (Биш)
B48: Mobile | C48: Ошский
B49: Mobile | C49: Внешние (Ош)
B51: Testing | C51: Бишкекский
...

Sheet Лист37
D3: июнь - июль
C4: 13п | D4: 77 | E4: 75 | F4: 2
C5: 12п
D7: активный | E7: прод
C8: май | D8: 8
C9: июнь | D9: 4 | E9: 6
C10: июль | D10: 2
C12: MedScan | D12: Баэль 70% Кубаныч 30%
E13: остаток
D14: аванс
C15: май | D15: 20000 | E15: 0 | F15: 20000
C16: июнь | D16: 25000 | E16: 5000 | F16: =D16+E16 -> 30000
C17: июль | D17: 10000 | E17: 25000 | F17: 35000
D19: =SUM(D14:D17) -> 55000 | E19: =SUM(E14:E17) -> 30000 | F19: =SUM(D19:E19) -> 85000

Sheet отчеты
A2: № | B2: месяц | D2: Проекты в разработке | G2: Количество проектов принятых заказчиком | J2: Количество незавершенных проектов | M2: стажеры | P2: выпускники | S2: Выбывшие из стажировки | W2: Внутренние собрания | AA2: внутреннык собрании
D3: Количество активных проектов | E3: Количество подписанных договоров на разработку | G3: проектов, принятых заказчиком за 110 дней после подписание договора | H3: Проекты, переданные заказчику с просрочкой | J3: прекращенные по инициативе исполнителя | K3: прекращенных по инициативе заказчика | M3: Активные стажеры | N3: Новые стажеры (из обшего числа) | P3: Успешно завершившие стажировку | Q3: % стажёров, добавленных в Банк резюме (из числа впервые проходящих стажировки) | S3: Отчисленные | T3: Прекратившие | U3: Приостановившие | W3: Запланированные | X3: Проведенные | Y3: Непроведенные | AA3: % посещаемости собраний | AB3: % неприсутствия
A4: 1 | B4: май | D4: 8 | E4: 2 | H4: 1
A5: 2 | B5: июнь | D5: 9 | E5: 4 | G5: 2 | H5: 1 | J5: 1
A6: 3 | B6: июль | D6: 10 | E6: 2
A7: 4 | B7: август
A8: 5 | B8: сентябрь
A9: 6 | B9: октябрь
A10: 7 | B10: ноябрь
A11: 8 | B11: декабрь

Sheet проекты
B1: Название проекта | C1: Место нахождения заказчика | D1: Тип проекта | E1: дата подписание договора | F1: дата акт-прием передачи | G1: Длительность проекта | H1: Контроль сроков | I1: ✅ Завершён | J1: 🚀 Продакшен | K1: 🔄 Доработка | L1: 🧪 Тестирование | M1: 💻 Разработка | N1: 🎨 Дизайн | O1: 📄 ТЗ | P1: месяц завершение | Q1: примечание
A3: 14.1 | H3: -----------------------
A4: 14.2 | H4: -----------------------
A5: 14.3 | H5: -----------------------
A6: 14.4 | H6: -----------------------
A7: 14.5 | H7: -----------------------
A8: 14.6 | H8: -----------------------
A9: 14.7 | H9: -----------------------
A11: 13.1 | B11: Олимпийская школа | C11: Бишкек | D11: 🌐 Веб-сайт | E11: 46160 | F11: 46250 | G11: =F11-E11 -> 90 | H11: 🟡 Риск задержки | P11: август
A12: 13.2 | B12: Омур клиника | C12: Ош | D12: 🌐 Веб-сайт | E12: 46126 | F12: 46216 | G12: =F12-E12 -> 90 | H12: 🟡 Риск задержки | P12: июль
A13: 13.3 | B13: ОБА | C13: Ош | D13: 🌐 Веб-сайт | E13: 46082 | F13: 46206 | G13: =F13-E13 -> 124 | H13: 🟠 Отставание | P13: июль
A14: 13.4 | B14: Ислам - медресе (Абдүшүкүр Нарматов) | C14: Ош | D14: 🌐 Веб-сайт | E14: 46161 | F14: 46251 | G14: =F14-E14 -> 90 | H14: 🟢 По графику | P14: август
A15: 13.5 | B15: Мин просвещения | C15: Бишкек | D15: 🌐 Веб-сайт | E15: 46196 | F15: 46286 | G15: =F15-E15 -> 90 | H15: 🟢 По графику | P15: сентябрь
A16: 13.6 | B16: Учкун | C16: Бишкек | D16: 🌐 Веб-сайт | G16: =F16-E16 -> 0 | H16: 🟢 По графику
A17: 13.7 | B17: Полароид | C17: Бишкек | D17: 🌐 Веб-сайт | G17: =F17-E17 -> 0 | H17: -----------------------
A19: 12.1 | B19: Гикс Про КЖ | C19: Бишкек | D19: 🌐 Веб-сайт | E19: 46090 | F19: 46173 | G19: =F19-E19 -> 83 | H19: 🟢 По графику | P19: май
A20: 12.2 | B20: ЛогоПарк | C20: Бишкек | D20: 🌐 Веб-сайт | G20: =F20-E20 -> 0 | H20: ----------------------- | O20: 🚫 Отменён
A21: 12.3 | B21: ПроМонтаж | C21: Бишкек | D21: 🌐 Веб-сайт | E21: 46090 | F21: 46172 | G21: =F21-E21 -> 82 | H21: 🟠 Отставание | P21: май
A22: 12.4 | B22: Энактас КЖ | C22: Бишкек | D22: 🌐 Веб-сайт | E22: 46090 | F22: 46148 | G22: =F22-E22 -> 58 | H22: 🟠 Отставание | P22: май
A23: 12.5 | B23: БиКлин | C23: Бишкек | D23: 📱 Моб- приложение | F23: 46234 | G23: =F23-E23 -> 46234 | H23: -----------------------
A25: 11.1 | B25: MedScan | C25: Бишкек | D25: 🌐 Веб-сайт | E25: 46072 | F25: 46192 | G25: =F25-E25 -> 120 | H25: 🔴 Просрочен | P25: апрель
A26: 11.2 | B26: OkuuKitebi | C26: Бишкек | D26: 🌐 Веб-сайт | E26: 45962 | F26: 46127 | G26: =F26-E26 -> 165 | H26: 🔴 Просрочен | P26: апрель
A27: 11.3 | B27: BeStyle | C27: Бишкек | D27: 🌐 Веб-сайт | E27: 46027 | F27: 46142 | G27: =F27-E27 -> 115 | H27: 🔴 Просрочен | P27: апрель
A28: 11.4 | B28: NBKR | C28: Бишкек | D28: 🌐 Веб-сайт | E28: 46074 | F28: 46111 | G28: =F28-E28 -> 37 | H28: ----------------------- | P28: март
A29: 11.5 | B29: EkiAl | C29: Бишкек | D29: 📱 Моб- приложение | G29: =F29-E29 -> 0 | H29: ----------------------- | O29: ❌ Клиент отказался
A30: 10.8 | B30: АДДК-Коледж | C30: Ош | D30: 🌐 Веб-сайт | E30: 45992 | F30: 46073 | G30: =F30-E30 -> 81 | H30: 🟢 По графику | P30: февраль
A31: 10.9 | B31: АДДК-академия | C31: Ош | D31: 🌐 Веб-сайт | E31: 45992 | F31: 46073 | G31: =F31-E31 -> 81 | H31: 🟢 По графику | P31: февраль
A32: 10.10 | B32: АДДК - Садик | C32: Ош | D32: 🌐 Веб-сайт | E32: 46113 | F32: 46203 | G32: =F32-E32 -> 90 | H32: 🔴 Просрочен | P32: июнь
A33: 10.11 | B33: АДДК - мектеп | C33: Ош | D33: 🌐 Веб-сайт | E33: 46113 | F33: 46203 | G33: =F33-E33 -> 90 | H33: 🔴 Просрочен | P33: июнь
A35: 10.1 | B35: technowomen | C35: Бишкек | D35: 🌐 Веб-сайт | E35: 45877 | F35: 46173 | G35: =F35-E35 -> 296 | H35: 🔴 Просрочен
A36: 10.2 | B36: Кыргыз экспорт | C36: Бишкек | D36: 🌐 Веб-сайт | E36: 45884 | F36: 46204 | G36: =F36-E36 -> 320 | H36: 🔴 Просрочен
A37: 10.3 | B37: happybaby | C37: Бишкек | D37: 🌐 Веб-сайт | E37: 45877 | F37: 46223 | G37: =F37-E37 -> 346 | H37: 🔴 Просрочен
A38: 10.4 | B38: Абир Финанс | C38: Бишкек | D38: 🌐 Веб-сайт | E38: 45873 | F38: 46223 | G38: =F38-E38 -> 350 | H38: 🔴 Просрочен
A39: 10.5 | B39: USTAT | C39: Бишкек | D39: 🌐 Веб-сайт | G39: =F39-E39 -> 0 | H39: 🔴 Просрочен | O39: ⏸️ Приостановлен
A40: 10.6 | B40: БАТ-МУ | C40: Бишкек | D40: 🌐 Веб-сайт | E40: 45877 | F40: 46043 | G40: =F40-E40 -> 166 | H40: 🔴 Просрочен | O40: ❌ Клиент отказался
A41: 10.7 | B41: Кок-Бел | C41: Ош | D41: 🌐 Веб-сайт | E41: 45931 | F41: 46053 | G41: =F41-E41 -> 122 | H41: 🔴 Просрочен

Sheet  (копия)
B1: Название проекта | C1: Место | D1: старт | E1: конец | F1: Длительность проекта | G1: Контроль сроков | H1: ✅ Завершён | I1: 🚀 Продакшен | J1: 🔄 Доработка | K1: 🧪 Тестирование | L1: 💻 Разработка | M1: 🎨 Дизайн | N1: 📄 ТЗ | O1: месяц завершение | P1: примечание
A2: 10 | B2: technowomen | C2: Бишкек | D2: 45877 | E2: 46173 | F2: =E2-D2 -> 296 | G2: 🔴 Просрочен | H2: 🚀 Продакшен
A3: 10 | B3: АДДК - Садик | C3: Ош | D3: 46113 | E3: 46203 | F3: =E3-D3 -> 90 | G3: 🔴 Просрочен | H3: 🚀 Продакшен | O3: июнь
A4: 10 | B4: АДДК - мектеп | C4: Ош | D4: 46113 | E4: 46203 | F4: =E4-D4 -> 90 | G4: 🔴 Просрочен | H4: 🚀 Продакшен | O4: июнь
A5: 10 | B5: Кыргыз экспорт | C5: Бишкек | D5: 45884 | E5: 46204 | F5: =E5-D5 -> 320 | G5: 🔴 Просрочен | H5: 🚀 Продакшен
A6: 10 | B6: happybaby | C6: Бишкек | D6: 45877 | E6: 46223 | F6: =E6-D6 -> 346 | G6: 🔴 Просрочен | H6: 🚀 Продакшен
A7: 10 | B7: Абир Финанс | C7: Бишкек | D7: 45873 | E7: 46223 | F7: =E7-D7 -> 350 | G7: 🔴 Просрочен | H7: 🚀 Продакшен
A8: 10 | B8: USTAT | C8: Бишкек | F8: =E8-D8 -> 0 | G8: 🔴 Просрочен | H8: ⏸️ Приостановлен
A9: 10 | B9: БАТ-МУ | C9: Бишкек | D9: 45877 | E9: 46043 | F9: =E9-D9 -> 166 | G9: 🔴 Просрочен | H9: ❌ Клиент отказался
A10: 10 | B10: Кок-Бел | C10: Ош | D10: 45931 | E10: 46053 | F10: =E10-D10 -> 122 | G10: 🔴 Просрочен | H10: ✅ Завершён
A11: 10 | B11: АДДК-Коледж | C11: Ош | D11: 45992 | E11: 46073 | F11: =E11-D11 -> 81 | G11: 🟢 По графику | H11: 🚀 Продакшен | O11: февраль
A12: 10 | B12: АДДК-академия | C12: Ош | D12: 45992 | E12: 46073 | F12: =E12-D12 -> 81 | G12: 🟢 По графику | H12: 🚀 Продакшен | O12: февраль
A13: 11 | B13: MedScan | C13: Бишкек | D13: 46072 | E13: 46192 | F13: =E13-D13 -> 120 | G13: 🔴 Просрочен | H13: ✅ Завершён | O13: апрель
A14: 11 | B14: OkuuKitebi | C14: Бишкек | D14: 45962 | E14: 46127 | F14: =E14-D14 -> 165 | G14: 🔴 Просрочен | H14: ✅ Завершён | O14: апрель
A15: 11 | B15: BeStyle | C15: Бишкек | D15: 46027 | E15: 46142 | F15: =E15-D15 -> 115 | G15: 🔴 Просрочен | H15: 🚀 Продакшен | O15: апрель
A16: 11 | B16: NBKR | C16: Бишкек | D16: 46074 | E16: 46111 | F16: =E16-D16 -> 37 | G16: ----------------------- | H16: ✅ Завершён | O16: март
A17: 11 | B17: EkiAl | C17: Бишкек | F17: =E17-D17 -> 0 | G17: ----------------------- | H17: ❌ Клиент отказался
A18: 12 | B18: Гикс Про КЖ | C18: Бишкек | D18: 46090 | E18: 46173 | F18: =E18-D18 -> 83 | G18: 🟢 По графику | H18: ✅ Завершён | O18: май
A19: 12 | B19: ЛогоПарк | C19: Бишкек | F19: =E19-D19 -> 0 | G19: ----------------------- | H19: 🚫 Отменён
A20: 12 | B20: Энактас КЖ | C20: Бишкек | D20: 46090 | E20: 46148 | F20: =E20-D20 -> 58 | G20: 🟠 Отставание | H20: 🚀 Продакшен | O20: май

Sheet Лист35 (копия)
B1: Название проекта | C1: Место нахождения заказчика | D1: Этап разработки | E1: Бишкекский филиал | F1: Внешние стажёры(Биш) | G1: Ошский филиал | H1: Внешние стажёры(Ош) | I1: всего | J1: 1-проекте | K1: Выбывшие из стажировки
E2: =SUM(E3:E12) -> 70 | F2: =SUM(F3:F12) -> 3 | G2: =SUM(G3:G12) -> 9 | H2: =SUM(H3:H12) -> 1 | I2: =SUM(I3:I12) -> 82 | J2: =SUM(J3:J12) -> 30
A3: 12 | B3: ПроМонтаж | C3: Бишкек | D3: 🧪 Тестирование | E3: 11 | G3: 1 | I3: =SUM(E3:H3) -> 12
A4: 13 | B4: ОБА | C4: Ош | D4: 💻 Разработка | E4: 11 | F4: 0 | G4: 4 | H4: 1 | I4: =SUM(E4:H4) -> 16 | J4: 15
A5: 13 | B5: Омур клиника | C5: Ош | D5: 🧪 Тестирование | E5: 14 | G5: 4 | I5: =SUM(E5:H5) -> 18
A6: 12 | B6: БиКлин | C6: Бишкек | D6: 💻 Разработка | E6: 6 | I6: =SUM(E6:H6) -> 6
A7: 13 | B7: Олимпийская школа | C7: Бишкек | D7: 💻 Разработка | E7: 16 | F7: 2 | I7: 17 | J7: 15
A8: 13 | B8: Ислам - медресе (Абдүшүкүр Нарматов) | C8: Ош | D8: 💻 Разработка | E8: 3 | F8: 1 | I8: =SUM(E8:H8) -> 4
A9: 13 | B9: Мин просвещения | C9: Бишкек | D9: 💻 Разработка | E9: 9 | F9: 0 | G9: 0 | H9: 0 | I9: =SUM(E9:H9) -> 9
I10: =SUM(E10:H10) -> 0
A11: 13 | B11: Учкун | C11: Бишкек | D11: 💻 Разработка | I11: =SUM(E11:H11) -> 0
A12: 13 | B12: Полароид | C12: Бишкек | I12: =SUM(E12:H12) -> 0
B17: Название проекта | C17: Место нахождения заказчика
B18: Полароид | C18: Бишкек
B19: Национальный парк «Кыргыз-Ата» | C19: Ош
B20: Магазин хозяйственных товаров | C20: Ош

Sheet тимлиды
A1: Название проекта | B1: Место нахождения заказчика | C1: PM | D1: UX/UI | E1: Backend | F1: Frontend | G1: Mobile | H1: Testing | I1: Backend
A11: Олимпийская школа | B11: Бишкек | D11: Жумабек | E11: Алишер | F11: Ислам
A12: Омур клиника | B12: Ош | D12: Жумабек | E12: Бексултан | F12: Ислам
A13: ОБА | B13: Ош | D13: Билол | E13: Алишер | F13: Ислам
A14: Ислам - медресе (Абдүшүкүр Нарматов) | B14: Ош | D14: Билол | E14: Саидахмат | F14: Ислам
A15: Мин просвещения | B15: Бишкек | D15: Жумабек | F15: Ислам
A16: Учкун | B16: Бишкек | D16: Жумабек | F16: Ислам
A17: Полароид | B17: Бишкек | D17: Билол
A19: Гикс Про КЖ | B19: Бишкек | E19: Эрбол | F19: Ислам
A20: ЛогоПарк | B20: Бишкек | E20: Эрбол | F20: Ислам
A21: ПроМонтаж | B21: Бишкек | E21: Саидахмат | F21: Ислам
A22: Энактас КЖ | B22: Бишкек | E22: Саидахмат | F22: Ислам
A23: БиКлин | B23: Бишкек | E23: Бекназар | G23: Ях
A25: MedScan | B25: Бишкек | E25: Эрбол | F25: Кубанычбек
A26: OkuuKitebi | B26: Бишкек | E26: Эрбол | F26: Кубанычбек
A27: BeStyle | B27: Бишкек | E27: Саидахмат | F27: Кубанычбек/Ислам
A28: NBKR | B28: Бишкек
A29: EkiAl | B29: Бишкек
A30: АДДК-Коледж | B30: Ош | E30: Эрбол | F30: Абдукарим
A31: АДДК-академия | B31: Ош | E31: Алишер | F31: Ислам
A32: АДДК - Садик | B32: Ош | E32: Алишер | F32: Ислам
A33: АДДК - мектеп | B33: Ош | E33: Алишер | F33: Ислам
A35: technowomen | B35: Бишкек | E35: Эрбол | F35: Ислам
A36: Кыргыз экспорт | B36: Бишкек | E36: Эрбол | F36: Ислам
A37: happybaby | B37: Бишкек | E37: Эрбол | F37: Ислам
A38: Абир Финанс | B38: Бишкек | E38: Эрбол | F38: Ислам
A39: USTAT | B39: Бишкек | E39: Саидахмат | F39: Ислам
A40: БАТ-МУ | B40: Бишкек
A41: Кок-Бел | B41: Ош | E41: Саидахмат | F41: Байэл

Sheet стажёры
A1: этап | B1: Название проекта | C1: Тип проекта | E1: Бишкекский филиал | F1: Внешние стажёры(Биш) | H1: Ошский филиал | I1: Внешние стажёры(Ош) | K1: Всего стажёров | M1: 1й проект | O1: завершили | Q1: Добавлен в Банк резюме | S1: примечание
E2: =COUNTIFS('Ведомость 13'!H:H,E1) -> 63 | F2: =COUNTIFS('Ведомость 13'!H:H,F1) -> 4 | H2: =COUNTIFS('Ведомость 13'!H:H,H1) -> 10 | I2: =COUNTIFS('Ведомость 13'!H:H,I1) -> 0 | K2: =SUM(E2:I2) -> 77
A4: 14.1
A5: 14.2
A6: 14.3
A7: 14.4
A8: 14.5
A9: 14.6
A10: 14.7
A12: 13.1 | B12: Олимпийская школа | C12: 🌐 Веб-сайт | E12: 16 | F12: 2 | K12: 17 | M12: 15
A13: 13.2 | B13: Омур клиника | C13: 🌐 Веб-сайт | E13: 14 | H13: 5 | K13: 19 | M13: 14
A14: 13.3 | B14: ОБА | C14: 🌐 Веб-сайт | E14: 11 | F14: 1 | H14: 4 | K14: 15 | M14: 14
A15: 13.4 | B15: Ислам - медресе (Абдүшүкүр Нарматов) | C15: 🌐 Веб-сайт | E15: 4 | F15: 1 | H15: 12 | K15: 17 | M15: 16
A16: 13.5 | B16: Мин просвещения | C16: 🌐 Веб-сайт | E16: 9 | K16: 9 | M16: 9
A17: 13.6 | B17: Учкун | C17: 🌐 Веб-сайт | E17: 9 | H17: 1 | K17: 10 | M17: 7
A18: 13.7 | B18: Полароид | C18: 🌐 Веб-сайт
A20: 12.1 | B20: Гикс Про КЖ | C20: 🌐 Веб-сайт | E20: 12 | F20: - | H20: 1 | K20: 13 | M20: 13 | O20: 13
A21: 12.2 | B21: ЛогоПарк | C21: 🌐 Веб-сайт | E21: 12 | K21: 12 | M21: 10
A22: 12.3 | B22: ПроМонтаж | C22: 🌐 Веб-сайт | E22: 11 | H22: 1 | K22: 12 | M22: 12
A23: 12.4 | B23: Энактас КЖ | C23: 🌐 Веб-сайт | E23: 19 | F23: 1 | H23: 3 | K23: 22 | M23: 20
A24: 12.5 | B24: БиКлин | C24: 📱 Моб- приложение | E24: 6 | K24: 6 | M24: 6
A26: 11.1 | B26: MedScan | C26: 🌐 Веб-сайт | E26: 7 | F26: - | H26: - | I26: - | K26: 7
A27: 11.2 | B27: OkuuKitebi | C27: 🌐 Веб-сайт | E27: 12 | F27: 1 | H27: - | I27: - | K27: 12 | M27: 10
A28: 11.3 | B28: BeStyle | C28: 🌐 Веб-сайт | E28: 13 | F28: 2 | H28: - | I28: - | K28: 13 | M28: 12
A29: 11.4 | B29: NBKR | C29: 🌐 Веб-сайт | E29: 20 | F29: 2 | H29: - | I29: - | K29: 20
A30: 11.5 | B30: EkiAl | C30: 📱 Моб- приложение | E30: 6 | K30: 6
A32: 10.1 | B32: technowomen | C32: 🌐 Веб-сайт | E32: 11 | F32: 2 | H32: - | I32: - | K32: 11
A33: 10.2 | B33: Кыргыз экспорт | C33: 🌐 Веб-сайт | E33: 13 | F33: - | H33: - | I33: - | K33: 13
A34: 10.3 | B34: happybaby | C34: 🌐 Веб-сайт | E34: 9 | F34: 1 | H34: - | I34: - | K34: 9
A35: 10.4 | B35: Абир Финанс | C35: 🌐 Веб-сайт | E35: 11 | F35: 2 | H35: - | I35: - | K35: 11
A36: 10.5 | B36: USTAT | C36: 🌐 Веб-сайт | E36: 12 | K36: 12
A37: 10.6 | B37: БАТ-МУ | C37: 🌐 Веб-сайт | E37: 11 | F37: 2 | H37: - | I37: - | K37: 11
A39: 9.1
A40: 9.2
A41: 9.3
A42: 9.4
A43: 9.5
A44: 9.6
A45: 9.7
A47: 8.1
...

Sheet собрании
A1: № | B1: дата | C1: дни | D1: этап проекта | E1: Тимлид | F1: проекты | G1: количество стажоров | H1: Присутствовали | I1: Отсутствовали | J1: Примечание
J2: =AVERAGE(J4:J32) -> #DIV/0!
J3: =H3/G3 -> #DIV/0!
A4: 1 | B4: 46143 | C4: пн | D4: ----------------------- | J4: =H4/G4 -> #DIV/0!
A5: 2 | B5: 46144 | C5: вт | D5: ----------------------- | J5: =H5/G5 -> #DIV/0!
A6: 3 | B6: 46145 | C6: ср | D6: ----------------------- | J6: =H6/G6 -> #DIV/0!
A7: 4 | B7: 46146 | C7: чт | D7: ----------------------- | G7: 6 | H7: 5 | I7: 1 | J7: =H7/G7 -> 0.83333333
A8: 5 | B8: 46147 | C8: пт | D8: ----------------------- | G8: 8 | H8: 3 | J8: =H8/G8 -> 0.375
A9: 6 | B9: 46148 | C9: сб | D9: ----------------------- | J9: =H9/G9 -> #DIV/0!
A10: 7 | B10: 46149 | C10: вс | J10: =H10/G10 -> #DIV/0!
A11: 8 | B11: 46150 | C11: пн | D11: ----------------------- | J11: =H11/G11 -> #DIV/0!
A12: 9 | B12: 46151 | C12: вт | D12: ----------------------- | J12: =H12/G12 -> #DIV/0!
A13: 10 | B13: 46152 | C13: ср | D13: ----------------------- | J13: =H13/G13 -> #DIV/0!
A14: 11 | B14: 46153 | C14: чт | D14: ----------------------- | G14: 6 | H14: 4 | I14: 2 | J14: =H14/G14 -> 0.66666667
A15: 12 | B15: 46154 | C15: пт | D15: ----------------------- | G15: 8 | H15: 6 | J15: =H15/G15 -> 0.75
A16: 13 | B16: 46155 | C16: сб | D16: ----------------------- | J16: =H16/G16 -> #DIV/0!
A17: 14 | B17: 46156 | C17: вс | J17: =H17/G17 -> #DIV/0!
A18: 15 | B18: 46157 | C18: пн | D18: ----------------------- | J18: =H18/G18 -> #DIV/0!
A19: 16 | B19: 46158 | C19: вт | D19: ----------------------- | G19: 6 | H19: 6 | J19: =H19/G19 -> 1
A20: 17 | B20: 46159 | C20: ср | D20: ----------------------- | J20: =H20/G20 -> #DIV/0!
A21: 18 | B21: 46160 | C21: чт | D21: ----------------------- | J21: =H21/G21 -> #DIV/0!
A22: 19 | B22: 46161 | C22: пт | D22: ----------------------- | G22: 8 | H22: 6 | J22: =H22/G22 -> 0.75
A23: 20 | B23: 46162 | C23: сб | D23: ----------------------- | J23: =H23/G23 -> #DIV/0!
A24: 21 | B24: 46163 | C24: вс | J24: =H24/G24 -> #DIV/0!
A25: 22 | B25: 46164 | C25: пн | D25: ----------------------- | J25: =H25/G25 -> #DIV/0!
A26: 23 | B26: 46165 | C26: вт | D26: ----------------------- | J26: =H26/G26 -> #DIV/0!
A27: 24 | B27: 46166 | C27: ср | D27: ----------------------- | J27: =H27/G27 -> #DIV/0!
A28: 25 | B28: 46167 | C28: чт | D28: ----------------------- | J28: =H28/G28 -> #DIV/0!
A29: 26 | B29: 46168 | C29: пт | D29: ----------------------- | G29: 14 | H29: 14 | J29: =H29/G29 -> 1
A30: 27 | B30: 46169 | C30: сб | D30: ----------------------- | J30: =H30/G30 -> #DIV/0!
A31: 28 | B31: 46170 | C31: вс | J31: =H31/G31 -> #DIV/0!
A32: 29 | B32: 46171 | C32: пн | D32: ----------------------- | J32: =H32/G32 -> #DIV/0!
A33: 30 | B33: 46172 | C33: вт | D33: ----------------------- | J33: =H33/G33 -> #DIV/0!
A34: 31 | B34: 46173 | C34: ср | D34: ----------------------- | J34: =H34/G34 -> #DIV/0!
A35: 32 | B35: 46174 | C35: чт | D35: ----------------------- | J35: =H35/G35 -> #DIV/0!
A36: 33 | B36: 46175 | C36: пт | D36: ----------------------- | G36: 8 | H36: 8 | J36: =H36/G36 -> 1
A37: 34 | B37: 46176 | C37: сб | D37: ----------------------- | J37: =H37/G37 -> #DIV/0!
A38: 35 | B38: 46177 | C38: вс | J38: =H38/G38 -> #DIV/0!
A39: 36 | B39: 46178 | C39: пн | D39: ----------------------- | G39: 5 | H39: 5 | J39: =H39/G39 -> 1
A40: 37 | B40: 46179 | C40: вт | D40: ----------------------- | G40: 5 | H40: 5 | J40: =H40/G40 -> 1
...

Sheet Ведомость 13
A1: поток | B1: Дата старта стажировки | C1: окончания стажировки | D1: направление | E1: название-проекта | F1: ФИО | G1: статус | H1: Канал поступления | I1: Очередность проекта | J1: Банк резюме | K1: Телефон | M1: NDA | N1: Телеграм | O1: Почта | P1: JIRA | Q1: GIT | R1: Discord | S1: Проекты стажёра | T1: Проекты стажёра | U1: Проекты стажёра | V1: Проекты стажёра
D2: PM | E2: Ислам - медресе(А.Нарматов) | F2: Айдана | G2: 🟢 Активный | H2: Бишкекский филиал | I2: 1й проект | J2: --------------- | K2: @craccol
D3: Backend | E3: Ислам - медресе(А.Нарматов) | F3: Усен Бектемиров | G3: 🟢 Активный | H3: Бишкекский филиал | I3: 1й проект | J3: --------------- | K3: @hhydrocone
D4: Frontend | E4: Ислам - медресе(А.Нарматов) | F4: Алимбек кызы Гулиза | G4: 🟢 Активный | H4: Бишкекский филиал | I4: 1й проект | J4: --------------- | K4: @renddtr 995196715
D5: Frontend | E5: Ислам - медресе(А.Нарматов) | F5: Курбанбаев Искендер Байышович | G5: 🟢 Активный | H5: Ошский филиал | I5: 1й проект | J5: --------------- | K5: @eu_4roboss
D6: Frontend | E6: Ислам - медресе(А.Нарматов) | F6: Раатбек Керимов | G6: 🟢 Активный | H6: Бишкекский филиал | I6: 1й проект | J6: --------------- | K6: 700550032 @raat_kerimov
D7: Frontend | E7: Ислам - медресе(А.Нарматов) | F7: Амантурова Фатима | G7: 🟢 Активный | H7: Бишкекский филиал | I7: 1й проект | J7: --------------- | K7: @HidekoLiones +996 505 893399
D8: Frontend | E8: Ислам - медресе(А.Нарматов) | F8: Мирвахидов Тохир | G8: 🟢 Активный | H8: Ошский филиал | I8: 1й проект | J8: --------------- | K8: 502146086 @mirvahidov_t
D9: Frontend | E9: Ислам - медресе(А.Нарматов) | F9: Тыныбеков Эмир | G9: 🟢 Активный | H9: Ошский филиал | I9: 1й проект | J9: --------------- | K9: 709 122 747 @Yusp1kR
D10: Frontend | E10: Ислам - медресе(А.Нарматов) | F10: Жумабаев Абай | G10: 🟢 Активный | H10: Ошский филиал | I10: 1й проект | J10: --------------- | K10: 220 541 318 @scabbard_999
D11: Backend | E11: Ислам - медресе(А.Нарматов) | F11: Адиев Нурсултан | G11: 🟢 Активный | H11: Бишкекский филиал | I11: 1й проект | J11: --------------- | K11: @nursultanad
D12: Backend | E12: Ислам - медресе(А.Нарматов) | F12: Азизулло Султанов | G12: 🟢 Активный | H12: Ошский филиал | I12: 1й проект | J12: --------------- | K12: @sultannnow
D13: Backend | E13: Ислам - медресе(А.Нарматов) | F13: Касымжанов Касым | G13: 🟢 Активный | H13: Ошский филиал | I13: 1й проект | J13: --------------- | K13: @Kasym0611
A14: 13.0 | B14: 46123 | D14: UX/UI | E14: Мин просвещения | F14: Шаршеналы кызы Айгерим | G14: 🟢 Активный | H14: Бишкекский филиал | I14: 1й проект | J14: --------------- | K14: @IIxexeII
A15: 13.0 | D15: UX/UI | E15: Мин просвещения | F15: Ишенкулов Нурболот | G15: 🟢 Активный | H15: Бишкекский филиал | I15: 1й проект | J15: --------------- | K15: @Nursweggg
A16: 13.0 | D16: UX/UI | E16: Мин просвещения | F16: Урбанович Рафаэль | G16: 🟢 Активный | H16: Бишкекский филиал | I16: 1й проект | J16: --------------- | K16: @wa1kerr
A17: 13.0 | D17: UX/UI | E17: Мин просвещения | F17: Рысбек кызы Раяна | G17: 🟢 Активный | H17: Бишкекский филиал | I17: 1й проект | J17: --------------- | K17: @iloveumar
A18: 13.0 | B18: 46160 | D18: UX/UI | E18: Мин просвещения | F18: Абдылдаева Алия | G18: 🟢 Активный | H18: Бишкекский филиал | I18: 1й проект | J18: --------------- | K18: @a1imai
A19: 13.0 | D19: UX/UI | E19: Мин просвещения | F19: Исабаева Фатима | G19: 🟢 Активный | H19: Бишкекский филиал | I19: 1й проект | J19: --------------- | K19: @dory_xw 0709324666
A20: 13.0 | D20: UX/UI | E20: Мин просвещения | F20: Зундуева Курманжан | G20: 🟢 Активный | H20: Бишкекский филиал | I20: 1й проект | J20: --------------- | K20: @vertsssww
A21: 13.0 | D21: UX/UI | E21: Мин просвещения | F21: Азимов Байэл | G21: 🟢 Активный | H21: Ошский филиал | I21: 1й проект | J21: --------------- | K21: @Bayelenko
D22: PM | E22: Мин просвещения | F22: Олег | G22: 🟢 Активный | H22: Бишкекский филиал | I22: 1й проект | J22: --------------- | K22: @Oleg_Pro312
D23: Backend | E23: Мин просвещения | F23: Мурадылжанов Абубакр | G23: 🟢 Активный | H23: Ошский филиал | I23: 1й проект | J23: --------------- | K23: 555212293 @Abubakr_jr
D24: Backend | E24: Мин просвещения | F24: Нурали уулу Ислам | G24: 🟢 Активный | H24: Внешние стажёры(Биш) | I24: 1й проект | J24: --------------- | K24: =+996778810761 -> 996778810761
A25: 13.0 | D25: Frontend | E25: ОБА | F25: Жигитекова Назик(Райана) второй проект | G25: 🟢 Активный | H25: Бишкекский филиал | I25: 2й проект | J25: ---------------
A26: 13.0 | D26: Backend | E26: ОБА | F26: Шактыбеков Даулет | G26: 🟢 Активный | H26: Бишкекский филиал | I26: 1й проект | J26: --------------- | K26: https://t.me/winnnqq
A27: 13.0 | D27: Backend | E27: ОБА | F27: Закирова Ассоль | G27: 🟢 Активный | H27: Бишкекский филиал | I27: 1й проект | J27: --------------- | K27: @zakir0vaa04
A28: 13.0 | B28: 46160 | D28: Backend | E28: ОБА | F28: Осоркулова Амина | G28: 🟢 Активный | H28: Бишкекский филиал | I28: 1й проект | J28: --------------- | K28: @awillovv
A29: 13.0 | B29: 46160 | D29: Frontend | E29: ОБА | F29: Белеков Азамат | G29: 🟢 Активный | H29: Внешние стажёры(Биш) | I29: 1й проект | J29: --------------- | K29: @azabvs
A30: 13.0 | B30: 46168 | D30: Frontend | E30: ОБА | F30: Кангельдиев Тимур | G30: 🟢 Активный | H30: Бишкекский филиал | I30: 1й проект | J30: --------------- | K30: @TimurKangeldiev
A31: 13.0 | D31: Frontend | E31: ОБА | F31: Абдыкапар уулу Улукбек | G31: 🟢 Активный | H31: Бишкекский филиал | I31: 1й проект | J31: --------------- | K31: @ulukbek_0307 996 501 425538
D32: PM | E32: ОБА | F32: Ават | G32: 🟢 Активный | H32: Бишкекский филиал | I32: 1й проект | J32: --------------- | K32: @kannisy
D33: Testing | E33: ОБА | F33: Бекбашев Айбек | G33: 🟢 Активный | H33: Бишкекский филиал | I33: 1й проект | J33: --------------- | K33: =+996708820764 -> 996708820764
A34: 13.0 | D34: UX/UI | E34: Олимпийская школа | F34: Айдаров Сабыр | G34: 🟢 Активный | H34: Бишкекский филиал | I34: 1й проект | J34: --------------- | K34: @sa6yx
A35: 13.0 | D35: UX/UI | E35: Олимпийская школа | F35: Джеенбекова Малика | G35: 🟢 Активный | H35: Бишкекский филиал | I35: 1й проект | J35: --------------- | K35: @mikoshh11
A36: 13.0 | D36: Testing | E36: Олимпийская школа | F36: Эсенова Нурайым | G36: 🟢 Активный | H36: Внешние стажёры(Биш) | I36: 1й проект | J36: --------------- | K36: @nuraiym205
A37: 13.0 | B37: 46121 | D37: UX/UI | E37: Олимпийская школа | F37: Тынчтыкбекова Айзель | G37: 🟢 Активный | H37: Бишкекский филиал | I37: 1й проект | J37: --------------- | K37: 709019138 @Grace0368
A38: 13.0 | B38: 46125 | D38: UX/UI | E38: Олимпийская школа | F38: Алапаев Умар | G38: 🟢 Активный | H38: Бишкекский филиал | I38: 1й проект | J38: --------------- | K38: @Iloverayka
A39: 13.0 | B39: 46128 | D39: UX/UI | E39: Олимпийская школа | F39: Решетун Данил | G39: 🟢 Активный | H39: Бишкекский филиал | I39: 1й проект | J39: --------------- | K39: @del_Rr +996702284724
A40: 13.0 | D40: Backend | E40: Олимпийская школа | F40: Аширматкулов Нурислам | G40: 🟢 Активный | H40: Бишкекский филиал | I40: 1й проект | J40: --------------- | K40: @user5721
...

Sheet Ресурсы проектов
B1: поток | C1: Проект | D1: Общий срок проекта | E1: Договор | F1: ТЗ | G1: Брендбук | H1: Дизайн | I1: стеджинг | J1: продакшн | K1: Резюме | L1: Gitlab | N1: Дискорд | O1: Jira | P1: Встреча тимлидов | Q1: организаторы собрании | S1: Project Manager | T1: Project Manager | U1: UX/UI | V1: Backend | X1: фронтенд | Z1: Flutter | AB1: QA | AC1: DevOps -инженер
A2: 2 | B2: 10 | C2: technowomen | D2: 46127 | F2: ТЗ | H2: дизайн | I2: technowoman.test.com.kg | J2: доступа нет | L2: https://gitlab.geeks.kg/technowoman | T2: Салтанат | W2: Эрбол Сайдакмат | X2: Айназик | Y2: Ислам | AC2: Нурсултан
A3: 3 | B3: 10 | C3: Кыргыз экспорт | D3: 46127 | H3: дизайн | I3: kyrgyz.geekspro.kg | J3: доступ алды. | L3: https://gitlab.geeks.kg/kyrgyzexport | T3: Айзирек | W3: Эрбол Сайдакмат | X3: Айназик | Y3: Ислам | AC3: Нурсултан
A4: 4 | B4: 10 | C4: happybaby | D4: 46127 | F4: ТЗ | H4: дизайн | I4: happy baby.geekspro.kg | J4: доступа нет студиодон алат | L4: https://gitlab.geeks.kg/happy-baby | T4: Перизат | W4: Адинай | X4: Айназик | Y4: Ислам | AC4: Нурсултан
A5: 6 | B5: 10 | C5: Абир Финанс | D5: 46127 | F5: ТЗ | H5: дизайн | I5: abiyir.geekspro.kg | J5: сервер не подходит | L5: https://gitlab.geeks.kg/abiyirfinance | T5: Бурулай | W5: Адинай | X5: Айназик | Y5: Ислам | AC5: Нурсултан
A6: 5 | B6: 10 | C6: USTAT | D6: ??????????? | F6: ТЗ | H6: дизайн | I6: - | T6: Арууке | W6: Адинай | X6: Айназик | Y6: Ислам | AC6: Нурсултан
A7: 7 | B7: 10 | C7: БАТ-МУ | D7: не вышел в прод. проект на стейдже остался | F7: ТЗ | H7: дизайн | I7: https://bsu.geekspro.kg/ | L7: https://gitlab.geeks.kg/batken-state-university | X7: Айназик | AC7: Нурсултан
A8: 8
A9: 9 | B9: 11 | C9: MedScan | D9: 19.02-31.03.-05.04 | F9: ТЗ | H9: Дизайн | I9: https://medscan.geekspro.kg | L9: Gitlab | T9: Айкен | U9: Азамат | V9: Умар Бекназар | W9: Эрбол Сайдакмат | X9: Адина | Y9: Баэль | AC9: Нурсултан
A10: 10 | B10: 11 | C10: OkuuKitebi | D10: 01.11.25-31.03.-15.04 | F10: ТЗ | H10: Дизайн | I10: https://okuukitebi.geekspro.kg/ | J10: https://okuukitebi.edu.kg/ | L10: Gitlab | P10: пн | T10: Кубаныч | U10: Азамат | V10: Умар Бекназар | W10: Эрбол Сайдакмат | X10: Адина | Y10: Баэль | AC10: Нурсултан
A11: 11 | B11: 11 | C11: BeStyle | D11: 05.01-30.04.26 | F11: ТЗ | H11: Дизайн | I11: https://bestyle.geekspro.kg/ | L11: Gitlab | O11: Jira | T11: Эркинай | U11: Азамат | V11: Умар Бекназар | W11: Эрбол Сайдакмат | X11: Адина | Y11: Баэль | AC11: Нурсултан
A12: 13 | B12: 11 | C12: NBKR | D12: ____-21.02.26 | H12: Дизайн | I12: https://nbkr.test.com.kg/ | J12: 30.03 чыгат протко. | L12: Gitlab | O12: Jira | T12: Кубаныч | U12: Азамат | V12: Умар Бекназар | W12: Эрбол Сайдакмат | X12: Адина | Y12: Баэль | AB12: Эмиль | AC12: Нурсултан
A13: 12 | B13: 11 | C13: EkiAl | D13: 21.11.25-30.04.2026 | F13: ТЗ | H13: Дизайн | L13: Gitlab | O13: Jira | T13: Кубаныч | U13: Азамат | V13: Умар Бекназар | W13: Эрбол Сайдакмат | X13: Адина | Y13: Адина | Z13: Имран | AA13: Жамалодин | AC13: Нурсултан
A15: 14 | B15: 12 | C15: GeeksPro | D15: 09.03.2026-31.05.26 | E15: Есть | F15: ТЗ | H15: Дизайн | L15: Gitlab | O15: Jira | T15: Адэль | W15: Эрбол Сайдакмат | X15: Баэль | Y15: Ислам | AC15: Нурсултан
A16: 15 | B16: 12 | C16: LogoPark | D16: 46090 | E16: Есть | F16: ТЗ | H16: Дизайн | L16: Gitlab | O16: Jira | T16: Чолпон | X16: Баэль | Y16: Ислам | AC16: Нурсултан
A17: 16 | B17: 12 | C17: ProMontage | D17: 09.03.2026-30.05.26 | E17: Есть | F17: ТЗ | H17: Дизайн | L17: Gitlab | O17: Jira | T17: Айгерим | X17: Баэль | Y17: Ислам | AC17: Нурсултан
A18: 17 | B18: 12 | C18: Enactus | D18: 09.03.2026-06.05.26 | E18: Есть | F18: ТЗ | H18: Дизайн | L18: Gitlab | O18: Jira | T18: Адилет | X18: Баэль | Y18: Ислам | AC18: Нурсултан
A19: 18 | B19: 12 | C19: BiClean | H19: Дизайн | T19: Кубаныч
A21: 18 | C21: Умай | F21: ТЗ | H21: Дизайн | L21: Gitlab | T21: Аяна | W21: Алишер | AC21: Нурсултан
A22: 19 | C22: КИТ форум | AC22: Нурсултан
A23: 20 | B23: 13 | C23: Олимпийский резерв | F23: ТЗ | T23: Аяна | W23: Алишер | Y23: Ислам
C24: Мин просвещения
C25: Палароид_Н
I41: =30000*88 -> 2640000

Sheet Ведомость 12
A1: поток | B1: Дата старта стажировки | C1: окончания стажировки | E1: направление | F1: название-проекта | G1: ФИО | H1: статус | I1: Канал поступления | J1: Очередность проекта | K1: Банк резюме | L1: Очередность проекта | M1: Телефон | N1: NDA | O1: Телеграм | P1: Почта | Q1: JIRA | R1: GIT | S1: Discord | T1: Проекты стажёра | U1: Проекты стажёра | V1: Проекты стажёра | W1: Проекты стажёра
A2: 12.0 | B2: 46066 | D2: 1 | E2: PM | F2: Гикс Про КЖ | G2: Бакытбекова Адэль | H2: 🟢 Активный | I2: Бишкекский филиал | J2: 1й проект | K2: --------------- | L2: 1й проект | M2: 709759681 | N2: -----
A3: 12.0 | B3: 46066 | D3: 2 | E3: Backend | F3: Гикс Про КЖ | G3: Аманкулов Чынгызхан | H3: 🟢 Активный | I3: Бишкекский филиал | J3: 1й проект | K3: --------------- | L3: 1й проект | M3: 502 624 333 | N3: -----
A4: 12.0 | B4: 46066 | D4: 3 | E4: Backend | F4: Гикс Про КЖ | G4: Адылбеков Элдияр | H4: 🟢 Активный | I4: Бишкекский филиал | J4: 1й проект | K4: --------------- | L4: 1й проект | M4: 505536622
A5: 12.0 | B5: 46106 | D5: 4 | E5: Backend | F5: Гикс Про КЖ | G5: Насиров Бэкастан-Ош | H5: 🟢 Активный | I5: Бишкекский филиал | J5: 1й проект | K5: --------------- | L5: 1й проект
A6: 12.0 | B6: 46066 | D6: 5 | E6: Testing | F6: Гикс Про КЖ | G6: Калдарова Айназик | H6: 🟢 Активный | I6: Бишкекский филиал | J6: 1й проект | K6: --------------- | L6: 1й проект | M6: 706694085
A7: 12.0 | B7: 46066 | D7: 6 | E7: Testing | F7: Гикс Про КЖ | G7: Насиза Имран | H7: 🟢 Активный | I7: Бишкекский филиал | J7: 1й проект | K7: --------------- | L7: 1й проект | M7: 509181020
A8: 12.0 | B8: 46066 | D8: 7 | E8: UX/UI | F8: Гикс Про КЖ | G8: Нартажиева Назима | H8: 🟢 Активный | I8: Бишкекский филиал | J8: 1й проект | K8: --------------- | L8: 1й проект | M8: 755028049 | N8: -----
A9: 12.0 | B9: 46066 | D9: 8 | E9: UX/UI | F9: Гикс Про КЖ | G9: Кенжебеков Кутман | H9: 🟢 Активный | I9: Бишкекский филиал | J9: 1й проект | K9: --------------- | L9: 1й проект | M9: 997570036 | N9: -----
A10: 12.0 | B10: 46066 | D10: 9 | E10: UX/UI | F10: Гикс Про КЖ | G10: Акимканова Асель | H10: 🟢 Активный | I10: Бишкекский филиал | J10: 1й проект | K10: --------------- | L10: 1й проект | M10: 502585792 | N10: -----
A11: 12.0 | B11: 46066 | D11: 10 | E11: Frontend | F11: Гикс Про КЖ | G11: Даниел Жолдошев(онлайн) | H11: 🟢 Активный | I11: Бишкекский филиал | J11: 1й проект | K11: --------------- | L11: 1й проект | M11: 779436768 | N11: -----
A12: 12.0 | B12: 46066 | D12: 11 | E12: Frontend | F12: Гикс Про КЖ | G12: Паншер Арафат | H12: 🟢 Активный | I12: Бишкекский филиал | J12: 1й проект | K12: --------------- | L12: 1й проект | M12: 755817222 | N12: -----
A13: 12.0 | E13: ------- | H13: 🟢 Активный | I13: Бишкекский филиал | J13: 1й проект | K13: --------------- | L13: 1й проект | N13: -----
A14: 12.0 | B14: 46069 | D14: 1 | E14: PM | F14: ЛогоПарк | G14: Камбаров Данияр | H14: 🟢 Активный | I14: Бишкекский филиал | J14: 1й проект | K14: --------------- | L14: 1й проект | M14: 999653738 | N14: -----
A15: 12.0 | B15: 46069 | D15: 2 | E15: Backend | F15: ЛогоПарк | G15: Тешебаев Эламан внешка | H15: 🟢 Активный | I15: Бишкекский филиал | J15: 1й проект | K15: --------------- | L15: 1й проект | M15: 708500047 | N15: -----
A16: 12.0 | B16: 46069 | D16: 3 | E16: Backend | F16: ЛогоПарк | G16: Тоокебаева Эльмира | H16: 🟢 Активный | I16: Бишкекский филиал | J16: 2й проект | K16: --------------- | L16: 2й проект | M16: 220 371254
A17: 12.0 | B17: 46106 | D17: 4 | E17: Backend | F17: ЛогоПарк | G17: Нургазиев Кутман - Ош | H17: 🟢 Активный | I17: Бишкекский филиал | J17: 1й проект | K17: --------------- | L17: 1й проект
A18: 12.0 | B18: 46069 | D18: 5 | E18: Testing | F18: Гикс Про КЖ | G18: Черняга Виктория внешка | H18: 🟢 Активный | I18: Бишкекский филиал | J18: 1й проект | K18: --------------- | L18: 1й проект | M18: 708112055 | N18: -----
A19: 12.0 | B19: 46069 | D19: 6 | E19: Testing | F19: ЛогоПарк | G19: Бакеев Бектур | H19: 🚪 Прекратил стажировку | I19: Бишкекский филиал | J19: 2й проект | K19: --------------- | L19: 2й проект | M19: @bugfxr | N19: -----
A20: 12.0 | B20: 46069 | D20: 7 | E20: UX/UI | F20: ЛогоПарк | G20: Байгазакова Аида | H20: 🟢 Активный | I20: Бишкекский филиал | J20: 1й проект | K20: --------------- | L20: 1й проект | M20: 551661620 | N20: -----
A21: 12.0 | B21: 46069 | D21: 8 | E21: UX/UI | F21: ЛогоПарк | G21: Асанбекова Сайкал | H21: 🟢 Активный | I21: Бишкекский филиал | J21: 1й проект | K21: --------------- | L21: 1й проект | M21: 555512105 @lakiassaikal | N21: -----
A22: 12.0 | B22: 46069 | D22: 9 | E22: UX/UI | F22: ЛогоПарк | G22: Батырбекова Бермет | H22: 🟢 Активный | I22: Бишкекский филиал | J22: 1й проект | K22: --------------- | L22: 1й проект | M22: 700402738 | N22: -----
A23: 12.0 | E23: ------- | H23: 🟢 Активный | I23: Бишкекский филиал | J23: 1й проект | K23: --------------- | L23: 1й проект | N23: -----
A24: 12.0 | B24: 46067 | D24: 1 | E24: PM | F24: ПроМонтаж | G24: Икрамова Айгерим | H24: 🟢 Активный | I24: Бишкекский филиал | J24: 1й проект | K24: --------------- | L24: 1й проект | M24: 776891388 | N24: -----
A25: 12.0 | B25: 46067 | D25: 2 | E25: Backend | F25: ПроМонтаж | G25: Сулайманов Даниел внешка | H25: 🟢 Активный | I25: Бишкекский филиал | J25: 1й проект | K25: --------------- | L25: 1й проект | M25: 707917151 | N25: -----
A26: 12.0 | B26: 46067 | D26: 3 | E26: Backend | F26: ПроМонтаж | G26: Исаева Канышай | H26: 🟢 Активный | I26: Бишкекский филиал | J26: 1й проект | K26: --------------- | L26: 1й проект | M26: 999300138 / @Kanya_East | N26: -----
A27: 12.0 | B27: 46067 | D27: 4 | E27: Backend | F27: ПроМонтаж | G27: Калиев Нурканат | H27: 🟢 Активный | I27: Бишкекский филиал | J27: 1й проект | K27: --------------- | L27: 1й проект | M27: @HIOSURO
A28: 12.0 | B28: 46106 | D28: 5 | E28: Backend | F28: ProMontage | G28: Искендер - Ош | H28: 🟢 Активный | I28: Бишкекский филиал | J28: 1й проект | K28: --------------- | L28: 1й проект | M28: @Iskenderlll
A29: 12.0 | B29: 46067 | D29: 6 | E29: Testing | F29: ПроМонтаж | G29: Пчелинцев Станислав | H29: 🟢 Активный | I29: Бишкекский филиал | J29: 1й проект | K29: --------------- | L29: 1й проект | M29: @Sosavodd | N29: -----
A30: 12.0 | B30: 46067 | D30: 7 | E30: Testing | F30: ПроМонтаж | G30: Казанцева Елена | H30: 🟢 Активный | I30: Бишкекский филиал | J30: 1й проект | K30: --------------- | L30: 1й проект | M30: @elhel_51 | N30: -----
A31: 12.0 | B31: 46067 | D31: 8 | E31: UX/UI | F31: ПроМонтаж | G31: Турумбекова Мираида | H31: 🟢 Активный | I31: Бишкекский филиал | J31: 1й проект | K31: --------------- | L31: 1й проект | M31: 500014004 | N31: -----
E32: UX/UI | F32: ПроМонтаж | G32: Рысбай кызы Айганыш | H32: 🟢 Активный | I32: Бишкекский филиал | J32: 1й проект | K32: --------------- | L32: 1й проект
A33: 12.0 | B33: 46097 | D33: 9 | E33: Frontend | F33: ПроМонтаж | G33: Бекболотов Нур | H33: 🟢 Активный | I33: Бишкекский филиал | J33: 1й проект | K33: --------------- | L33: 1й проект | M33: @nurxdev | N33: -----
A34: 12.0 | B34: 46097 | D34: 10 | E34: Frontend | F34: ПроМонтаж | G34: Кульчуков Далер | H34: 🟢 Активный | I34: Бишкекский филиал | J34: 1й проект | K34: --------------- | L34: 1й проект | M34: 702 006213 @reducer02
A35: 12.0 | E35: ------- | H35: 🟢 Активный | I35: Бишкекский филиал | J35: 1й проект | K35: --------------- | L35: 1й проект | N35: -----
A36: 12.0 | B36: 46068 | D36: 1 | E36: PM | F36: Энактас КЖ | G36: Кочербаев Адилет | H36: 🟢 Активный | I36: Бишкекский филиал | J36: 1й проект | K36: --------------- | L36: 1й проект | M36: 503351506 | N36: -----
A37: 12.0 | B37: 46068 | D37: 2 | E37: Frontend | F37: Энактас КЖ | G37: Бекеев Турат внешка | H37: 🟢 Активный | I37: Бишкекский филиал | J37: 1й проект | K37: --------------- | L37: 1й проект | M37: 997020664 | N37: -----
A38: 12.0 | B38: 46068 | D38: 3 | E38: Backend | F38: Энактас КЖ | G38: Жейренбаева Атайым внешка | H38: 🟢 Активный | I38: Бишкекский филиал | J38: 1й проект | K38: --------------- | L38: 1й проект | M38: 553552631 | N38: -----
A39: 12.0 | B39: 46068 | D39: 4 | E39: Backend | F39: Энактас КЖ | G39: Токторбеков Максат | H39: 🟢 Активный | I39: Бишкекский филиал | J39: 1й проект | K39: --------------- | L39: 1й проект | M39: 550179370
A40: 12.0 | B40: 46068 | D40: 5 | E40: Backend | F40: Энактас КЖ | G40: Рахатова Алтынай | H40: 🟢 Активный | I40: Бишкекский филиал | J40: 1й проект | K40: --------------- | L40: 1й проект | M40: 551713517
...

Sheet черн-статистика
L1: Алек
B2: название | C2: PM | D2: UX/UI | E2: Frontend | F2: Backend | G2: Testing | H2: всего стаж. | I2: завершили | J2: банк резюме | K2: статусы:
B3: =COUNTA(B13:B32) -> 19 | C3: =C12+C18+C24 -> 15 | D3: =D12+D18+D24 -> 41 | E3: =E12+E18+E24 -> 50 | F3: =F12+F18+F24 -> 57 | G3: =G12+G18+G24 -> 21 | H3: =H12+H18+H24 -> 184
B5: =COUNTA(B6:B11) -> 6 | C5: =SUM(C6:C10) -> 5 | D5: =SUM(D6:D10) -> 15 | E5: =SUM(E6:E10) -> 12 | F5: =SUM(F6:F10) -> 16 | G5: =SUM(G6:G10) -> 5 | H5: =SUM(H6:H11) -> 65
A6: 46032 | B6: technowomen | C6: 1 | D6: 3 | E6: 3 | F6: 3 | G6: 1 | H6: =SUM(C6:G6) -> 11 | K6: сдан
A7: 46063 | B7: Кыргыз экспорт | C7: 1 | D7: 3 | E7: 2 | F7: 3 | G7: 1 | H7: =SUM(C7:G7) -> 10 | K7: продакшн | L7: ? | M7: 46204 | R7: девопс-практика-слава-внутренный продажа
A8: 46091 | B8: happybaby | C8: 1 | D8: 3 | E8: 2 | F8: 3 | G8: 1 | H8: =SUM(C8:G8) -> 10 | K8: продакшн | M8: 46204 | R8: старты гикспро
A9: 46122 | B9: Абир Финанс | C9: 1 | D9: 3 | E9: 2 | F9: 3 | G9: 1 | H9: =SUM(C9:G9) -> 10 | K9: продакшн | L9: домен | R9: онлайн -демо дей-пр.эфир
A10: 46152 | B10: USTAT | C10: 1 | D10: 3 | E10: 3 | F10: 4 | G10: 1 | H10: =SUM(C10:G10) -> 12 | K10: На паузе | R10: мобилный проект
A11: 46183 | B11: БАТ-МУ | C11: 1 | D11: 3 | E11: 3 | F11: 4 | G11: 1 | H11: =SUM(C11:G11) -> 12 | K11: Клиент отказался | R11: стр-план
B12: =COUNTA(B13:B17) -> 5 | C12: =SUM(C13:C17) -> 5 | D12: =SUM(D13:D17) -> 15 | E12: =SUM(E13:E17) -> 21 | F12: =SUM(F13:F17) -> 20 | G12: =SUM(G13:G17) -> 7 | H12: =SUM(H13:H17) -> 68 | R12: 20:00:00 пн собр с пм
A13: 46033 | B13: MedScan | C13: 1 | D13: 3 | E13: 2 | F13: 2 | G13: 1 | H13: =SUM(C13:G13) -> 9 | K13: сдан | R13: видео-моушн
A14: 46064 | B14: OkuuKitebi | C14: 1 | D14: 2 | E14: 4 | F14: 3 | G14: 2 | H14: =SUM(C14:G14) -> 12 | K14: сдан | R14: статусы проектов
A15: 46092 | B15: BeStyle | C15: 1 | D15: 4 | E15: 3 | F15: 3 | G15: 2 | H15: =SUM(C15:G15) -> 13 | K15: стеджинг | R15: кол.студентов
A16: 46123 | B16: NBKR | C16: 1 | D16: 4 | E16: 7 | F16: 7 | G16: 1 | H16: =SUM(C16:G16) -> 20 | K16: сдан | R16: старт-завершение проекты
A17: 46153 | B17: EkiAl | C17: 1 | D17: 2 | E17: 5 | F17: 5 | G17: 1 | H17: =SUM(C17:G17) -> 14 | K17: Клиент отказался | L17: команда получила проект БиКлин | R17: инфо-повот
B18: =COUNTA(B19:B23) -> 5 | C18: =SUM(C19:C23) -> 5 | D18: =SUM(D19:D23) -> 13 | E18: =SUM(E19:E23) -> 16 | F18: =SUM(F19:F23) -> 25 | G18: =SUM(G19:G23) -> 9 | H18: =SUM(H19:H23) -> 68 | R18: гикс кж. инстограмм инфо
A19: 46034 | B19: Гикс Про КЖ | C19: =COUNTIFS('Ведомость 12'!F:F,B19,'Ведомость 12'!E:E,$C$2) -> 1 | D19: =COUNTIFS('Ведомость 12'!F:F,B19,'Ведомость 12'!E:E,$D$2) -> 3 | E19: =COUNTIFS('Ведомость 12'!F:F,B19,'Ведомость 12'!E:E,$E$2) -> 2 | F19: =COUNTIFS('Ведомость 12'!F:F,B19,'Ведомость 12'!E:E,$F$2) -> 3 | G19: =COUNTIFS('Ведомость 12'!F:F,B19,'Ведомость 12'!E:E,$G$2) -> 3 | H19: =SUM(C19:G19) -> 12 | I19: 11 | J19: 10 | K19: сдан | R19: серификаттары
A20: 46065 | B20: ЛогоПарк | C20: =COUNTIFS('Ведомость 12'!F:F,B20,'Ведомость 12'!E:E,$C$2) -> 1 | D20: =COUNTIFS('Ведомость 12'!F:F,B20,'Ведомость 12'!E:E,$D$2) -> 3 | E20: =COUNTIFS('Ведомость 12'!F:F,B20,'Ведомость 12'!E:E,$E$2) -> 3 | F20: =COUNTIFS('Ведомость 12'!F:F,B20,'Ведомость 12'!E:E,$F$2) -> 4 | G20: =COUNTIFS('Ведомость 12'!F:F,B20,'Ведомость 12'!E:E,$G$2) -> 1 | H20: =SUM(C20:G20) -> 12 | K20: Проект отклонен | R20: встреча с смм специалисты Асель
A21: 46093 | B21: ПроМонтаж | C21: =COUNTIFS('Ведомость 12'!F:F,B21,'Ведомость 12'!E:E,$C$2) -> 1 | D21: =COUNTIFS('Ведомость 12'!F:F,B21,'Ведомость 12'!E:E,$D$2) -> 2 | E21: =COUNTIFS('Ведомость 12'!F:F,B21,'Ведомость 12'!E:E,$E$2) -> 2 | F21: =COUNTIFS('Ведомость 12'!F:F,B21,'Ведомость 12'!E:E,$F$2) -> 3 | G21: =COUNTIFS('Ведомость 12'!F:F,B21,'Ведомость 12'!E:E,$G$2) -> 2 | H21: =SUM(C21:G21) -> 10 | K21: стеджинг | R21: стажор менен аяктоо каерде
A22: 46124 | B22: Энактас КЖ | C22: =COUNTIFS('Ведомость 12'!F:F,B22,'Ведомость 12'!E:E,$C$2) -> 1 | D22: =COUNTIFS('Ведомость 12'!F:F,B22,'Ведомость 12'!E:E,$D$2) -> 3 | E22: =COUNTIFS('Ведомость 12'!F:F,B22,'Ведомость 12'!E:E,$E$2) -> 4 | F22: =COUNTIFS('Ведомость 12'!F:F,B22,'Ведомость 12'!E:E,$F$2) -> 10 | G22: =COUNTIFS('Ведомость 12'!F:F,B22,'Ведомость 12'!E:E,$G$2) -> 2 | H22: =SUM(C22:G22) -> 20 | K22: стеджинг | R22: ИИ смм Асель
A23: 46154 | B23: БиКлин | C23: 1 | D23: 2 | E23: 5 | F23: 5 | G23: 1 | H23: =SUM(C23:G23) -> 14 | K23: в разработке | R23: стажор -стейджингди тушунуш керек
B24: =COUNTA(B25:B30) -> 6 | C24: =SUM(C25:C29) -> 5 | D24: =SUM(D25:D29) -> 13 | E24: =SUM(E25:E29) -> 13 | F24: =SUM(F25:F29) -> 12 | G24: =SUM(G25:G29) -> 5 | H24: =SUM(H25:H29) -> 48 | R24: 22.07-03.08
A25: 46035 | B25: Олимпийская школа | C25: =COUNTIFS('Ведомость 13'!E:E,$B$25,'Ведомость 13'!D:D,C2) -> 1 | D25: =COUNTIFS('Ведомость 13'!E:E,$B$25,'Ведомость 13'!D:D,D2) -> 5 | E25: =COUNTIFS('Ведомость 13'!E:E,$B$25,'Ведомость 13'!D:D,E2) -> 5 | F25: =COUNTIFS('Ведомость 13'!E:E,$B$25,'Ведомость 13'!D:D,F2) -> 4 | G25: =COUNTIFS('Ведомость 13'!E:E,$B$25,'Ведомость 13'!D:D,G2) -> 1 | H25: =SUM(C25:G25) -> 16 | K25: в разработке | R25: собраные девопс
A26: 46066 | B26: Омур клиника | C26: =COUNTIFS('Ведомость 13'!E:E,B26,'Ведомость 13'!D:D,C2) -> 1 | D26: ОШ | E26: =COUNTIFS('Ведомость 13'!E:E,B26,'Ведомость 13'!D:D,E2) -> 4 | F26: =COUNTIFS('Ведомость 13'!E:E,B26,'Ведомость 13'!D:D,F2) -> 5 | G26: =COUNTIFS('Ведомость 13'!E:E,B26,'Ведомость 13'!D:D,G2) -> 3 | H26: =SUM(C26:G26) -> 13 | K26: стеджинг
A27: 46094 | B27: ОБА | C27: =COUNTIFS('Ведомость 13'!E:E,B27,'Ведомость 13'!D:D,C2) -> 1 | D27: ОШ | E27: =COUNTIFS('Ведомость 13'!E:E,B27,'Ведомость 13'!D:D,E2) -> 4 | F27: =COUNTIFS('Ведомость 13'!E:E,B27,'Ведомость 13'!D:D,F2) -> 3 | G27: =COUNTIFS('Ведомость 13'!E:E,B27,'Ведомость 13'!D:D,G2) -> 1 | H27: =SUM(C27:G27) -> 9 | K27: в разработке
A28: 46125 | B28: Ислам - медресе(А.Нарматов) | C28: 1 | D28: ОШ | H28: =SUM(C28:G28) -> 1 | K28: в разработке
A29: 46155 | B29: Мин просвещения | C29: =COUNTIFS('Ведомость 13'!E:E,B29,'Ведомость 13'!D:D,C2) -> 1 | D29: =COUNTIFS('Ведомость 13'!E:E,B29,'Ведомость 13'!D:D,D2) -> 8 | H29: =SUM(C29:G29) -> 9 | K29: в разработке
A30: 46186 | B30: Учкун | C30: 1 | D30: =COUNTIFS('Ведомость 13'!E:E,B30,'Ведомость 13'!D:D,D2) -> 4 | E30: =COUNTIFS('Ведомость 13'!E:E,B30,'Ведомость 13'!D:D,E2) -> 0 | F30: =COUNTIFS('Ведомость 13'!E:E,B30,'Ведомость 13'!D:D,F2) -> 0 | G30: =COUNTIFS('Ведомость 13'!E:E,B30,'Ведомость 13'!D:D,G2) -> 0 | H30: =SUM(C30:G30) -> 5 | K30: в разработке
A31: 46216 | B31: Полароид

Sheet Справочник
A1: 1 | B1: ФИО | C1: место полож. | D1: Участники | E1: тел.номер | F1: телеграммы | G1: э.почты | H1: Discord | I1: Jira
A2: 2 | B2: Мураталиев Дастан | C2: Бишкек | D2: руководитель
A3: 3 | B3: Саимбетов Нурсултан | C3: Ош | D3: DevOps-инженер
A4: 4 | B4: Анабел | C4: Бишкек | D4: Project Manager
A5: 5 | B5: Сабиржанов Жамолдин | C5: Ош | D5: Flatter
A6: 6 | B6: Курманбеков Эрбол | C6: Ош | D6: Backend
A7: 7 | B7: Мийзамбеков Баэль | C7: Ош | D7: Frontend
A8: 8 | B8: Талантбек уулу Саидахмад | C8: Ош | D8: Backend
A9: 9 | B9: Эмиль | C9: Бишкек | D9: QА | F9: телеграмм
A10: 10 | C10: Бишкек | D10: UX/UI
A11: 11 | B11: Салиев Жумабек | C11: Ош | D11: UX/UI
A12: 12 | B12: Исакова Кудбухон | C12: Ош | D12: UX/UI
A13: 13
A14: 14 | B14: Айкен | C14: Бишкек | D14: Project Manager
A15: 15 | B15: Кубаныч | C15: Бишкек | D15: Project Manager
A16: 16 | B16: Эркинай | C16: Бишкек | D16: Project Manager
A17: 17 | B17: Салия | C17: Бишкек | D17: Project Manager | F17: нет проекта ЭкиАл
B19: ФИО | C19: Направление | D19: Проект | E19: Номер телефона | F19: Телеграмм | G19: Оплата | H19: Договор | I19: Комментарии
A20: 18 | B20: Иминжан уулу Мардон | C20: Backend | E20: 996555204445 | F20: @Mari_programm | G20: бп | H20: есть
A21: 19 | B21: Чынберди уулу Бекастан | C21: Backend | E21: 996990867606 | F21: @beka_stan | G21: бп | H21: есть
A22: 20 | B22: Нуралиев Ислам | C22: Frontend | E22: 996552110176 | F22: @L_WIII | G22: бп | H22: есть
A23: 21 | B23: Абдикалилов Ислам | C23: Frontend | E23: 996 501 155095 | F23: @Abdikalilov_Islam | G23: бп | H23: есть
A24: 22 | B24: ДЖоробаев Билолдин | C24: UX/UI | E24: 5590440772 | F24: телеграмм | G24: бп | H24: есть

Sheet Ведомость 11
A1: 1 | B1: 1 | C1: поток | D1: Дата старта стажировки | E1: окончания стажировки | G1: направление | H1: название-проекта | I1: ФИО | J1: статус | K1: Канал поступления | L1: Очередность проекта | M1: Банк резюме | N1: Телефон | O1: NDA | P1: Телеграм | Q1: Почта | R1: JIRA | S1: GIT | T1: Discord | U1: Проекты стажёра | V1: Проекты стажёра | W1: Проекты стажёра | X1: Проекты стажёра
C2: 11 | G2: бэкенд | I2: Атай Кайырдинов | J2: 🟢 Активный | K2: Бишкекский филиал | L2: 1й проект | M2: --------------- | N2: @Someonefine +996 778 400484
J3: 🟢 Активный | K3: Бишкекский филиал | L3: 1й проект | M3: ---------------
J4: 🟢 Активный | K4: Бишкекский филиал | L4: 1й проект | M4: ---------------
J5: 🟢 Активный | K5: Бишкекский филиал | L5: 1й проект | M5: ---------------
J6: 🟢 Активный | K6: Бишкекский филиал | L6: 1й проект | M6: ---------------
J7: 🟢 Активный | K7: Бишкекский филиал | L7: 1й проект | M7: ---------------
J8: 🟢 Активный | K8: Бишкекский филиал | L8: 1й проект | M8: ---------------
J9: 🟢 Активный | K9: Бишкекский филиал | L9: 1й проект | M9: ---------------
J10: 🟢 Активный | K10: Бишкекский филиал | L10: 1й проект | M10: ---------------
J11: 🟢 Активный | K11: Бишкекский филиал | L11: 1й проект | M11: ---------------
J12: 🟢 Активный | K12: Бишкекский филиал | L12: 1й проект | M12: ---------------
J13: 🟢 Активный | K13: Бишкекский филиал | L13: 1й проект | M13: ---------------
J14: 🟢 Активный | K14: Бишкекский филиал | L14: 1й проект | M14: ---------------
... J53: ---------------- | K53: ----------------- | L53: 1й проект | M53: ---------------

Sheet BiClean
A1: БиКлин | B1: Кубанычбек | C1: Телефон | D1: Телеграм | E1: Почта | F1: JIRA | G1: NDA | H1: GIT
A2: UX/UI | B2: Арстанбеков Ильхам | C2: 552305510 | D2: @iarstanbekov | E2: ilham.arstan@gmail.com | F2: добавлен
A3: UX/UI | B3: Марасулова Айзира
A4: Backend | B4: Асан уулу Мавлидин | C4: 701024755 | D4: @Asanovv1ch
A5: Backend | B5: Черванев Рамзан | D5: @rmzbjj
A6: Backend | B6: Нарынбеков Артур | D6: @lissaboncr7
A7: Backend | B7: Абдыгапар уулу Абдыкалык | D7: нет никнейма
A8: Backend | B8: Омурзаков Байэмир | C8: 0555422842 | E8: baemir.omurzak0v@mail.ru | F8: baemir_omurzak0v
A10: Mobile | B10: Доолотбеков Султан | C10: 559 484 874 | D10: @s_doolotbekov
A11: Mobile | B11: Талипов Азамат | D11: @talazaa
A12: Mobile | B12: Илья Игольников | D12: @Ilya2_17
A13: Mobile | B13: Кошойбаев Искандер | C13: 555 194109
A14: Mobile | B14: Токтаалиев Дияр | C14: @d1ccaaa | D14: @d1ccaaa
A17: Testing | B17: Асангулова Айжан | C17: 708 154 521 | D17: нет никнейма
A18: Testing | B18: Таалайбек уулу Байэли | D18: @wiasslo
A21: Ст.тимлид диз | B21: Бейшеналиева Алия | C21: 702951774 | D21: @scarrley
B22: Камбарбеков Азамат | C22: 553120044 | D22: @Azkmbw
A23: Ст.тимлид фронт
A25: Ст. тимлид бэкенд
A29: UX/UI | B29: Решетун Данил | D29: @del_Rr
A30: Frontend | B30: Исмаилов Алибек | C30: 550118335 | D30: @jjfnnnn1t | E30: alibekismailov223@gmail.com
A31: Frontend | B31: Талантбек кызы Сезим | C31: 504758777 | D31: @sezim_talantbek | E31: sezim240298m21@mail.ru | F31: 1
A32: Frontend | B32: Мамбетжанова Жазайым | C32: 555185503 | D32: @Zhazaiym03 | E32: mambetzhanovazhazaiym@gmail.com | F32: 1

Sheet BeStyle
A1: BeStyle | B1: Эркинай | C1: Телефон | D1: Телеграм | E1: Почта | F1: JIRA | G1: NDA | H1: GIT
A2: UX/UI | B2: Абдылдаева Саида | C2: 555582502 | D2: @a770s
A3: UX/UI | B3: Кулукеева Бегимай | C3: 709453556 | D3: нет юзернейма | E3: bkulukeeva1@gmail.com | F3: 1
A4: UX/UI | B4: Рахимов Атай | C4: 755640440 | D4: @User_number10 | E4: genij8901@gmail.com | F4: 1
A5: UX/UI | B5: Алтынай Джыргалбекова | C5: 755866906 | D5: @urmattovas | E5: altunai2009@icloud.com | F5: 1
A6: Backend | B6: Кочкорбай уулу Айсултан | C6: 555 782 189 | D6: @DiamondDogs5 | E6: broassassin932@gmail.com | F6: 1
A7: Backend | B7: Нурсултан Исаев | C7: 220722827 | D7: @isaevv_zzz | E7: aibeknurel07@gmail.com | F7: 1
A8: Backend | B8: Бекназар Узбеков | C8: 999 906 710 | D8: @JailBreak077 | E8: tsstark225@gmail.com | F8: 1
A9: Frontend | B9: Уктам Тентиев | D9: @quazsc | E9: messitopgoat@gmail.com | F9: 1
A10: Frontend | B10: Исмаилов Алибек | C10: 550118335 | D10: @jjfnnnn1t | E10: alibekismailov223@gmail.com | F10: 1
A11: Frontend | B11: Мамбетжанова Жазайым | C11: 555185503 | D11: @Zhazaiym03 | E11: mambetzhanovazhazaiym@gmail.com | F11: 1
A12: Testing | B12: Тажибаева Райхан | C12: 708 896 964 | D12: @basilbasil_06 | E12: tazhibaeva.raikhan@gmail.com | F12: 1
A13: Testing | B13: Муслим Садыков | C13: 509 357 643 | D13: @muslim9876543212 | E13: m4413626@gmail.com | F13: 1
A15: Ст.тимлид диз | B15: Бейшеналиева Алия | C15: 702951774 | D15: @scarrley
B16: Камбарбеков Азамат | C16: 553120044 | D16: @Azkmbw
A17: Ст.тимлид фронт
A19: Ст. тимлид бэкенд | B19: Бекназар Узбеков | C19: 999 906 710 | D19: @JailBreak077 | E19: tsstark225@gmail.com | F19: 1

Sheet Окуу Китеби
A1: Окуу китеби | B1: Кубанычбек | C1: Телефон | D1: Телеграм | E1: Почта | F1: JIRA | G1: NDA | H1: GIT
A2: UX/UI | B2: Абдылдаева Саида | C2: 555582502 | D2: @a770s
A3: UX/UI | B3: Адилет Жаныбек уулу | C3: 703 545 316 | D3: @Adiscary
A4: Backend | B4: Дунлаза Сумая | D4: @tthe_ds
A5: Backend | B5: Бектенов Арсен | D5: @arseni_be
A6: Backend | B6: Сагынбаев Амантур | D6: @Amansss3838
A8: Frontend | B8: Элиза Атанбаева | C8: 777787406 | D8: @eliza72_32
A9: Frontend | B9: Жигитекова Назик | C9: 7 911 746-39-50 | D9: нет никнейма
A10: Frontend | B10: Рыскулова Жибек | D10: @zh1kaa
A11: Frontend | B11: Эламан Жумабеков | D11: @ElamanDev
A12: Testing | B12: Темирбекова Эльмира | C12: 557 369 613 | D12: 995 557 369 613
A13: Testing | B13: Матисаков Нурсултан | C13: 509980055 | D13: @Nam_ra_00
A16: Ст.тимлид диз | B16: Бейшеналиева Алия | C16: 702951774 | D16: @scarrley
B17: Камбарбеков Азамат | C17: 553120044 | D17: @Azkmbw
A18: Ст.тимлид фронт
A20: Ст. тимлид бэкенд

Sheet Медскан
A1: Медскан | B1: Айкен | C1: Телефон | D1: Телеграм | E1: Почта | F1: JIRA | G1: NDA | H1: GIT
A2: UX/UI | B2: Садыкова Диора | D2: @minttear6 | E2: sadykovadiora@mail.ru | F2: sadykova_diora
A3: UX/UI | B3: Абдуллаев Мелис | C3: 996 552 115150 | D3: @Meeellliiis | F3: Melis Abdullaev
A4: Backend | B4: Исаев Нурсултан | D4: @isaevv_zzz | F4: nursultan_isaev
A6: Frontend | B6: Асан Акжол | D6: @pascal1356 | E6: akjolasan75@gmail.com | F6: asan_akjol
A7: Frontend | B7: Кубанычбеков Амантур | D7: @amanturdev_7 | E7: kubanycbekovamantur2@gmail.com | F7: kubanycbekov_amantur
A8: Frontend
A9: Testing | B9: Данияр Кенжебеков | C9: @AnEnterpreneur | D9: @AnEnterpreneur | E9: kenjebekov.daniyar.1409@gmail.com | F9: kenjebekov_daniyar
A11: Ст.тимлид диз
A13: Ст.тимлид фронт
A15: Ст. тимлид бэкенд
A18: UX/UI | B18: Джыргалбекова Алтынай | D18: @urmattovas
A19: Backend | B19: Атай Кайырдинов | D19: @Someonefine

Sheet Встречи с заказчиком
A1: № | B1: Проекты | C1: Договор | D1: ТЗ | E1: Резюме | F1: Брендбук
A2: 1 | H2: 7
A3: 2 | H3: 12
A4: 3 | H4: 13
A5: 4 | H5: 17
A6: 5
A7: 6

Sheet Расписание встреч
A1: Расписания менторов | B1: Егор Frontend | C1: Арзыбек Backend | D1: Ux/Ui Айгерим | F1: Батма ПМ | G1: Алина QA | N1: Нурсултан iOS
A2: Пн
A3: Вт | D3: Вторник в 17:00
A4: Ср | D4: Среда в 17:00
A5: Чт
A6: Пт
A7: Сб
A10: № | C10: Даты предзащит 25% | D10: факт даты защиты | E10: PM | F10: UX/UI | G10: Backend | H10: Frontend | I10: Android | J10: IOS | K10: Test | L10: итого ср.показ.
A11: 1 | E11: 0.25 | F11: 0 | G11: 0 | H11: 0 | K11: 0 | L11: =(E11+F11+G11+H11+K11)/5 -> 0.05
A12: 2 | E12: 0.25 | F12: 0 | G12: 0 | H12: 0 | K12: 0 | L12: =(E12+F12+G12+H12+K12)/5 -> 0.05
A13: 3 | E13: 0.25 | F13: 0 | G13: 0 | H13: 0 | K13: 0 | L13: =(E13+F13+G13+H13+K13)/5 -> 0.05
A14: 4 | E14: 0.25 | F14: 0 | G14: 0 | H14: 0 | K14: 0 | L14: =(E14+F14+G14+H14+K14)/5 -> 0.05
A15: 5 | E15: 0.25 | F15: 0 | G15: 0 | H15: 0 | K15: 0 | L15: =(E15+F15+G15+H15+K15)/5 -> 0.05
A16: 6 | E16: 0.25 | F16: 0 | G16: 0 | H16: 0 | K16: 0 | L16: =(E16+F16+G16+H16+K16)/5 -> 0.05
A18: № | C18: Даты предзащит 50% | D18: факт дата защиты | E18: PM | F18: UX/UI | G18: Backend | H18: Frontend | I18: Android | J18: IOS | K18: Test | L18: итого ср.показ.
A19: 1 | E19: 0 | F19: 0 | G19: 0 | H19: 0 | K19: 0 | L19: =(E19+F19+G19+H19+K19)/5 -> 0
A20: 2 | E20: 0 | F20: 0 | G20: 0 | H20: 0 | K20: 0 | L20: =(E20+F20+G20+H20+K20)/5 -> 0
A21: 3 | E21: 0 | F21: 0 | G21: 0 | H21: 0 | K21: 0 | L21: =(E21+F21+G21+H21+K21)/5 -> 0
A22: 4 | E22: 0 | F22: 0 | G22: 0 | H22: 0 | K22: 0 | L22: =(E22+F22+G22+H22+K22)/5 -> 0
A23: 5 | E23: 0 | F23: 0 | G23: 0 | H23: 0 | K23: 0 | L23: =(E23+F23+G23+H23+K23)/5 -> 0
A24: 6 | E24: 0 | F24: 0 | G24: 0 | H24: 0 | K24: 0 | L24: =(E24+F24+G24+H24+K24)/5 -> 0
A26: № | C26: Даты предзащит 75% | D26: факт дата защиты | E26: PM | F26: UX/UI | G26: Backend | H26: Frontend | I26: Android | J26: IOS | K26: Test | L26: итого ср.показ.
A27: 1 | E27: 0 | F27: 0 | G27: 0 | H27: 0 | K27: 0 | L27: =(E27+F27+G27+H27+K27)/5 -> 0
A28: 2 | E28: 0 | F28: 0 | G28: 0 | H28: 0 | K28: 0 | L28: =(E28+F28+G28+H28+K28)/5 -> 0
A29: 3 | E29: 0 | F29: 0 | G29: 0 | H29: 0 | K29: 0 | L29: =(E29+F29+G29+H29+K29)/5 -> 0
A30: 4 | E30: 0 | F30: 0 | G30: 0 | H30: 0 | K30: 0 | L30: =(E30+F30+G30+H30+K30)/5 -> 0
A31: 5 | E31: 0 | F31: 0 | G31: 0 | H31: 0 | K31: 0 | L31: =(E31+F31+G31+H31+K31)/5 -> 0
A32: 6 | E32: 0 | F32: 0 | G32: 0 | H32: 0 | K32: 0 | L32: =(E32+F32+G32+H32+K32)/5 -> 0
A34: № | C34: Даты предзащит 100% | D34: факт дата защиты | E34: PM | F34: UX/UI | G34: Backend | H34: Frontend | I34: Android | J34: IOS | K34: Test | L34: итого ср.показ.
A35: 1 | E35: 0 | F35: 0 | G35: 0 | H35: 0 | K35: 0 | L35: =(E35+F35+G35+H35+K35)/5 -> 0
A36: 2 | E36: 0 | F36: 0 | G36: 0 | H36: 0 | K36: 0 | L36: =(E36+F36+G36+H36+K36)/5 -> 0
A37: 3 | E37: 0 | F37: 0 | G37: 0 | H37: 0 | K37: 0 | L37: =(E37+F37+G37+H37+K37)/5 -> 0
A38: 4 | E38: 0 | F38: 0 | G38: 0 | H38: 0 | K38: 0 | L38: =(E38+F38+G38+H38+K38)/5 -> 0
A39: 5 | E39: 0 | F39: 0 | G39: 0 | H39: 0 | K39: 0 | L39: =(E39+F39+G39+H39+K39)/5 -> 0
A40: 6 | E40: 0 | F40: 0 | G40: 0 | H40: 0 | K40: 0 | L40: =(E40+F40+G40+H40+K40)/5 -> 0
A42: МК по Soft Skills | B42: 1 | C42: 2 | D42: 3 | E42: 4 | F42: 5
A43: Дата
A44: PM
A45: UX/UI
A46: UX/UI
...

Sheet Фронт
A1: Список участников : | B1: дата :
B2: 45940
A3: Манчеллаев Владислав | B3: TRUE
A4: Бакиров Даниэль | B4: TRUE
A5: Джантелиев Адилхан | B5: TRUE
A6: Мурсалиев Нурсултан | B6: FALSE
A7: Токтоматов Айтенир | B7: TRUE
A8: Тентимишов Азамат | B8: TRUE
A9: Джеенбекова Сакина | B9: FALSE
A10: Орозбеков Жаныбек | B10: TRUE
A11: Усенканов Саади | B11: FALSE
A12: Конушбек уулу Эмир | B12: FALSE
A13: Айдана Курбанбекова | B13: TRUE
A14: Кайыпова Салкын | B14: TRUE
A15: Амина Кыйрабаева | B15: FALSE

Sheet Дизайн
A1: Список участников: | B1: дата:
B2: 45889
A3: Дивазов Фархад | B3: 1
A4: Сасыков Улан | B4: 0
A5: Алиаскарова Аяна | B5: 1
A6: Алдыракманова Айбийке | B6: 1
A7: Юрьев Иван | B7: 0
A8: Раимбекова Айя | B8: 1
A9: Жумаев Нурислам | B9: 1
A10: Анарбекова Канышай | B10: 1
A11: Талантбекова Ринне | B11: 1
A12: Шаршеева Жибек | B12: 0
A13: Арстанбеков Ильхам ! | B13: 1
A14: Бейшеналиева Алия | B14: 1
... A19: Яйха Егана | B19: 1
A20: Абдуллаев Мелис
A21: Жумакадырова Аина
A22: Окенов Адиль
A23: Мавлянов Мухаммадсодик

Sheet Беки 
A1: Список студентов : | B1: дата
B2: 45888
A3: Нурланов Арген | B3: 1
A4: Юбуров Амир | B4: 1
A5: Исмаев Селим | B5: 1
A6: Юлдашев Диорбек | B6: 1
A7: Эсенбеков Тимур | B7: 1
A8: Заиров Умар | B8: 1
A9: Бекназар Болотов | B9: 1
A10: Тоокебаева Эльмира | B10: 1
A11: Курманов Тилек | B11: 1
A12: Дунлаза Сумая | B12: 1
A13: Нарымбаев Ильдан | B13: 1
A14: Бекбоева Адина | B14: 1
... A26: Ишенбеков Эржан | B26: 1
